<robot name="pingpongbot" xmlns:xacro="http://www.ros.org/wiki/xacro">
    <xacro:property name="params_yaml" value="$(find pingpongbot_description)/config/params.yaml"/>
    <xacro:property name="yaml_dict" value="${xacro.load_yaml(params_yaml)['/**']['ros__parameters']}"/>
    <xacro:property name="wheel_radius" value="${yaml_dict['wheel_radius']}"/>
    <xacro:property name="wheel_thickness" value="${yaml_dict['wheel_thickness']}"/>
    <xacro:property name="wheel_offset_radius" value="${yaml_dict['wheel_offset_radius']}"/>
    <xacro:property name="origin_to_chassis_top" value="${yaml_dict['origin_to_chassis_top']}"/>
    <xacro:property name="paddle_origin_offset" value="${yaml_dict['paddle_origin_offset']}"/>

    <material name="white">
        <color rgba="1 1 1 1"/>
    </material>

    <link name="base_footprint"/>

    <joint name="base_joint" type="fixed">
        <parent link="base_footprint"/>
        <child link="base_link"/>
        <origin xyz="0.0 0.0 ${wheel_radius}" rpy="0 0 0"/>
    </joint>

    <link name="base_link">
        <visual>
            <origin xyz="0.0 0.0 0.0" rpy="0 0 ${pi}"/>
            <geometry>
                <mesh filename="package://pingpongbot_description/meshes/chassis.stl" scale="1.0 1.0 1.0"/>
            </geometry>
            <material name="white"/>
        </visual>

        <collision>
            <origin xyz="0.0 0.0 0.0" rpy="0 0 0"/>
            <geometry>
                <mesh filename="package://pingpongbot_description/meshes/chassis.stl" scale="1.0 1.0 1.0"/>
            </geometry>
        </collision>
    </link>

    <joint name="wheel1_joint" type="continuous">
        <parent link="base_link"/>
        <child link="wheel1"/>
        <origin xyz="0.0 ${wheel_offset_radius} 0.0" rpy="${pi/2} 0 ${pi}"/>
        <axis xyz="0 0 1"/>
    </joint>

    <link name="wheel1">
        <visual>
            <origin xyz="0.0 0.0 0.0" rpy="0 0 0"/>
            <geometry>
                <mesh filename="package://pingpongbot_description/meshes/omniwheel.stl" scale="1.0 1.0 1.0"/>
            </geometry>
            <material name="white"/>
        </visual>

        <collision>
            <origin xyz="0.0 0.0 0.0" rpy="0 0 0"/>
            <geometry>
                <cylinder length="${wheel_thickness}" radius="${wheel_radius}"/>
            </geometry>
        </collision>
    </link>

    <joint name="wheel2_joint" type="continuous">
        <parent link="base_link"/>
        <child link="wheel2"/>
        <origin xyz="${wheel_offset_radius*sin(pi/3)} ${-wheel_offset_radius*cos(pi/3)} 0.0" rpy="${pi/2} 0 ${pi/3}"/>
        <axis xyz="0 0 1"/>
    </joint>

    <link name="wheel2">
        <visual>
            <origin xyz="0.0 0.0 0.0" rpy="0 0 0"/>
            <geometry>
                <mesh filename="package://pingpongbot_description/meshes/omniwheel.stl" scale="1.0 1.0 1.0"/>
            </geometry>
            <material name="white"/>
        </visual>

        <collision>
            <origin xyz="0.0 0.0 0.0" rpy="0 0 0"/>
            <geometry>
                <cylinder length="${wheel_thickness}" radius="${wheel_radius}"/>
            </geometry>
        </collision>
    </link>

    <joint name="wheel3_joint" type="continuous">
        <parent link="base_link"/>
        <child link="wheel3"/>
        <origin xyz="${-wheel_offset_radius*sin(pi/3)} ${-wheel_offset_radius*cos(pi/3)} 0.0" rpy="${pi/2} 0 ${-pi/3}"/>
        <axis xyz="0 0 1"/>
    </joint>

    <link name="wheel3">
        <visual>
            <origin xyz="0.0 0.0 0.0" rpy="0 0 0"/>
            <geometry>
                <mesh filename="package://pingpongbot_description/meshes/omniwheel.stl" scale="1.0 1.0 1.0"/>
            </geometry>
            <material name="white"/>
        </visual>

        <collision>
            <origin xyz="0.0 0.0 0.0" rpy="0 0 0"/>
            <geometry>
                <cylinder length="${wheel_thickness}" radius="${wheel_radius}"/>
            </geometry>
        </collision>
    </link>

    <joint name="base_to_paddle" type="fixed">
        <parent link="base_link"/>
        <child link="paddle"/>
        <origin xyz="0.0 0.0 ${origin_to_chassis_top}" rpy="0 0 0"/>
    </joint>

    <link name="paddle">
        <visual>
            <origin xyz="0.0 0.0 ${paddle_origin_offset}" rpy="0 0 0"/>
            <geometry>
                <mesh filename="package://pingpongbot_description/meshes/paddle.stl" scale="1.0 1.0 1.0"/>
            </geometry>
            <material name="white"/>
        </visual>

        <collision>
            <origin xyz="0.0 0.0 ${paddle_origin_offset}" rpy="0 0 0"/>
            <geometry>
                <mesh filename="package://pingpongbot_description/meshes/paddle.stl" scale="1.0 1.0 1.0"/>
            </geometry>
        </collision>
    </link>

</robot>